Workbook

Sheet lookup_OPUS_split_strategy2
A1: direction_key | B1: winner_model | C1: winner_avg_score | D1: num_sentences | E1: rate_per_hour | F1: est_hours
A2: abk_Cyrl-abk_Cyrl | B2: qwen3-4b-instruct-2507 | C2: unknown | D2: 14650 | E2: 20 | F2: 0.7
A3: abk_Cyrl-bos_Latn | B3: qwen3-4b-instruct-2507 | C3: unknown | D3: 23494 | E3: 20 | F3: 1.2
A4: abk_Cyrl-ces_Latn | B4: metricx24 | C4: unknown | D4: 71481 | E4: 300 | F4: 0.2
A5: abk_Cyrl-dan_Latn | B5: metricx24 | C5: unknown | D5: 53175 | E5: 300 | F5: 0.2
A6: abk_Cyrl-deu_Latn | B6: metricx24 | C6: unknown | D6: 77231 | E6: 300 | F6: 0.3
A7: abk_Cyrl-ell_Grek | B7: metricx24 | C7: unknown | D7: 80380 | E7: 300 | F7: 0.3
A8: abk_Cyrl-eng_Latn | B8: metricx24 | C8: unknown | D8: 99246 | E8: 300 | F8: 0.3
A9: abk_Cyrl-est_Latn | B9: metricx24 | C9: unknown | D9: 23506 | E9: 300 | F9: 0.1
A10: abk_Cyrl-eus_Latn | B10: metricx24 | C10: unknown | D10: 14371 | E10: 300 | F10: 0
A11: abk_Cyrl-fas_Arab | B11: qwen3-4b-instruct-2507 | C11: unknown | D11: 61087 | E11: 20 | F11: 3.1
A12: abk_Cyrl-fin_Latn | B12: metricx24 | C12: unknown | D12: 62027 | E12: 300 | F12: 0.2
A13: abk_Cyrl-fra_Latn | B13: metricx24 | C13: unknown | D13: 79663 | E13: 300 | F13: 0.3
... A36: ace_Latn-ace_Latn | B36: qwen3-4b-instruct-2507 | C36: unknown | D36: 21633 | E36: 20 | F36: 1.1
A37: ace_Latn-ceb_Latn | B37: m-prometheus-7b | C37: 0.78542061 | D37: 118211 | E37: 15 | F37: 7.9
A38: ace_Latn-eng_Latn | B38: metricx24 | C38: 0.778317 | D38: 2133701 | E38: 300 | F38: 7.1
A39: ace_Latn-jav_Latn | B39: m-prometheus-7b | C39: 0.82561971 | D39: 108321 | E39: 15 | F39: 7.2
A40: ace_Latn-por_Latn | B40: qwen3-4b-instruct-2507 | C40: 0.841573 | D40: 70908 | E40: 20 | F40: 3.5
A41: ace_Latn-rus_Cyrl | B41: shaomutan_remedy-9b-22 | C41: 0.87937384 | D41: 63197 | E41: 33 | F41: 1.9
A42: ace_Latn-war_Latn | B42: qwen3-4b-instruct-2507 | C42: 0.774599 | D42: 101125 | E42: 20 | F42: 5.1
A43: acm_Arab-bul_Cyrl | B43: qwen3-4b-instruct-2507 | C43: 0.952583 | D43: 115374 | E43: 20 | F43: 5.8
A44: acm_Arab-ces_Latn | B44: qwen3-4b-instruct-2507 | C44: 0.946605 | D44: 130398 | E44: 20 | F44: 6.5
A45: acm_Arab-dan_Latn | B45: qwen3-4b-instruct-2507 | C45: 0.932195 | D45: 103600 | E45: 20 | F45: 5.2
A46: acm_Arab-deu_Latn | B46: qwen3-4b-instruct-2507 | C46: 0.942842 | D46: 135894 | E46: 20 | F46: 6.8
A47: acm_Arab-ell_Grek | B47: qwen3-4b-instruct-2507 | C47: 0.939094 | D47: 142979 | E47: 20 | F47: 7.1
A48: acm_Arab-eng_Latn | B48: qwen3-4b-instruct-2507 | C48: 0.965844 | D48: 264891 | E48: 20 | F48: 13.2
A49: acm_Arab-fas_Arab | B49: metricx24 | C49: unknown | D49: 121267 | E49: 300 | F49: 0.4
A50: acm_Arab-fin_Latn | B50: shaomutan_remedy-9b-22 | C50: 0.91994582 | D50: 127222 | E50: 33 | F50: 3.9
A51: acm_Arab-fra_Latn | B51: qwen3-4b-instruct-2507 | C51: 0.946023 | D51: 171994 | E51: 20 | F51: 8.6
A52: acm_Arab-heb_Hebr | B52: qwen3-4b-instruct-2507 | C52: 0.936939 | D52: 125353 | E52: 20 | F52: 6.3
A53: acm_Arab-hrv_Latn | B53: qwen3-4b-instruct-2507 | C53: 0.934136 | D53: 97784 | E53: 20 | F53: 4.9
A54: acm_Arab-hun_Latn | B54: qwen3-4b-instruct-2507 | C54: 0.937536 | D54: 134447 | E54: 20 | F54: 6.7
A55: acm_Arab-ind_Latn | B55: shaomutan_remedy-9b-22 | C55: 0.92530282 | D55: 130829 | E55: 33 | F55: 4
A56: acm_Arab-ita_Latn | B56: qwen3-4b-instruct-2507 | C56: 0.954395 | D56: 143414 | E56: 20 | F56: 7.2
A57: acm_Arab-nld_Latn | B57: shaomutan_remedy-9b-22 | C57: 0.93316714 | D57: 152150 | E57: 33 | F57: 4.6
A58: acm_Arab-pol_Latn | B58: qwen3-4b-instruct-2507 | C58: 0.933136 | D58: 154675 | E58: 20 | F58: 7.7
A59: acm_Arab-por_Latn | B59: qwen3-4b-instruct-2507 | C59: 0.93676 | D59: 180233 | E59: 20 | F59: 9
A60: acm_Arab-ron_Latn | B60: qwen3-4b-instruct-2507 | C60: 0.946705 | D60: 166235 | E60: 20 | F60: 8.3
A61: acm_Arab-rus_Cyrl | B61: qwen3-4b-instruct-2507 | C61: 0.941528 | D61: 123049 | E61: 20 | F61: 6.2
... A63: acm_Arab-spa_Latn | B63: shaomutan_remedy-9b-22 | C63: 0.94033973 | D63: 196725 | E63: 33 | F63: 6
...

Sheet new_analysis
A1: model | B1: sentence rate | C1: sentences_per_sec | D1: sentences_per_hour
A2: xcomet-xl | B2: 30000/270 sec | C2: =30000/270 -> 111.11111 | D2: =C2*3600 -> 400000
A3: wmt23-cometkiwi-da-xl | B3: 30000/600 sec | C3: =30000/600 -> 50 | D3: =C3*3600 -> 180000
A4: shaomutan_remedy-9b-22 | B4: 16500/290 sec | C4: =16500/290 -> 56.896552 | D4: =C4*3600 -> 204827.59
A5: qwen3-4b-instruct-2507 | B5: 10000/1250 sec | C5: =10000/1250 -> 8 | D5: =C5*3600 -> 28800
A6: metricx24 | B6: 50000/150 sec | C6: =50000/150 -> 333.33333 | D6: =C6*3600 -> 1200000
A7: m-prometheus-7b | B7: 7500/1000 sec | C7: =7500/1000 -> 7.5 | D7: =C7*3600 -> 27000
A8: bicleaner-ai | B8: 125000/ 200 sec | C8: =125000/200 -> 625 | D8: =C8*3600 -> 2250000

Sheet analysis
A1: model_name | B1: number_of_directions | C1: est_hours | E1: model_name | F1: number_of_directions | G1: est_hours_new | H1: sentences_per_hour
A2: bicleaner-ai | B2: =COUNTIF(lookup_OPUS_split_strategy2!$B:$B,A2) -> 26 | C2: =SUMIF(lookup_OPUS_split_strategy2!$B:$B,A2,lookup_OPUS_split_strategy2!$F:$F) -> 512.9 | E2: bicleaner-ai | F2: =COUNTIF(lookup_OPUS_split_strategy2!$B:$B,E2) -> 26 | G2: =IF(H2="","",SUMIF(lookup_OPUS_split_strategy2!$B:$B,E2,lookup_OPUS_split_strategy2!$D:$D)/H2) -> 57.018716 | H2: =IFERROR(VLOOKUP(E2,new_analysis!$A:$D,4,FALSE),"") -> 2250000
A3: m-prometheus-7b | B3: =COUNTIF(lookup_OPUS_split_strategy2!$B:$B,A3) -> 84 | C3: =SUMIF(lookup_OPUS_split_strategy2!$B:$B,A3,lookup_OPUS_split_strategy2!$F:$F) -> 12152.4 | E3: m-prometheus-7b | F3: =COUNTIF(lookup_OPUS_split_strategy2!$B:$B,E3) -> 84 | G3: =IF(H3="","",SUMIF(lookup_OPUS_split_strategy2!$B:$B,E3,lookup_OPUS_split_strategy2!$D:$D)/H3) -> 6751.344 | H3: =IFERROR(VLOOKUP(E3,new_analysis!$A:$D,4,FALSE),"") -> 27000
A4: metricx24 | B4: =COUNTIF(lookup_OPUS_split_strategy2!$B:$B,A4) -> 4453 | C4: =SUMIF(lookup_OPUS_split_strategy2!$B:$B,A4,lookup_OPUS_split_strategy2!$F:$F) -> 140152.5 | E4: metricx24 | F4: =COUNTIF(lookup_OPUS_split_strategy2!$B:$B,E4) -> 4453 | G4: =IF(H4="","",SUMIF(lookup_OPUS_split_strategy2!$B:$B,E4,lookup_OPUS_split_strategy2!$D:$D)/H4) -> 35038.808 | H4: =IFERROR(VLOOKUP(E4,new_analysis!$A:$D,4,FALSE),"") -> 1200000
A5: qwen3-14b | B5: =COUNTIF(lookup_OPUS_split_strategy2!$B:$B,A5) -> 0 | C5: =SUMIF(lookup_OPUS_split_strategy2!$B:$B,A5,lookup_OPUS_split_strategy2!$F:$F) -> 0 | E5: qwen3-14b | F5: =COUNTIF(lookup_OPUS_split_strategy2!$B:$B,E5) -> 0 | G5: 0 | H5: 0
A6: qwen3-4b-instruct-2507 | B6: =COUNTIF(lookup_OPUS_split_strategy2!$B:$B,A6) -> 2180 | C6: =SUMIF(lookup_OPUS_split_strategy2!$B:$B,A6,lookup_OPUS_split_strategy2!$F:$F) -> 48030.7 | E6: qwen3-4b-instruct-2507 | F6: =COUNTIF(lookup_OPUS_split_strategy2!$B:$B,E6) -> 2180 | G6: =IF(H6="","",SUMIF(lookup_OPUS_split_strategy2!$B:$B,E6,lookup_OPUS_split_strategy2!$D:$D)/H6) -> 33355.057 | H6: =IFERROR(VLOOKUP(E6,new_analysis!$A:$D,4,FALSE),"") -> 28800
A7: qwen3-8b | B7: =COUNTIF(lookup_OPUS_split_strategy2!$B:$B,A7) -> 0 | C7: =SUMIF(lookup_OPUS_split_strategy2!$B:$B,A7,lookup_OPUS_split_strategy2!$F:$F) -> 0 | E7: qwen3-8b | F7: =COUNTIF(lookup_OPUS_split_strategy2!$B:$B,E7) -> 0 | G7: 0 | H7: 0
A8: shaomutan_remedy-9b-22 | B8: =COUNTIF(lookup_OPUS_split_strategy2!$B:$B,A8) -> 3102 | C8: =SUMIF(lookup_OPUS_split_strategy2!$B:$B,A8,lookup_OPUS_split_strategy2!$F:$F) -> 100581.4 | E8: shaomutan_remedy-9b-22 | F8: =COUNTIF(lookup_OPUS_split_strategy2!$B:$B,E8) -> 3102 | G8: =IF(H8="","",SUMIF(lookup_OPUS_split_strategy2!$B:$B,E8,lookup_OPUS_split_strategy2!$D:$D)/H8) -> 16204.807 | H8: =IFERROR(VLOOKUP(E8,new_analysis!$A:$D,4,FALSE),"") -> 204827.59
A9: wmt23-cometkiwi-da-xl | B9: =COUNTIF(lookup_OPUS_split_strategy2!$B:$B,A9) -> 1 | C9: =SUMIF(lookup_OPUS_split_strategy2!$B:$B,A9,lookup_OPUS_split_strategy2!$F:$F) -> 1.6 | E9: wmt23-cometkiwi-da-xl | F9: =COUNTIF(lookup_OPUS_split_strategy2!$B:$B,E9) -> 1 | G9: =IF(H9="","",SUMIF(lookup_OPUS_split_strategy2!$B:$B,E9,lookup_OPUS_split_strategy2!$D:$D)/H9) -> 0.54234444 | H9: =IFERROR(VLOOKUP(E9,new_analysis!$A:$D,4,FALSE),"") -> 180000
A10: xcomet-xl | B10: =COUNTIF(lookup_OPUS_split_strategy2!$B:$B,A10) -> 4 | C10: =SUMIF(lookup_OPUS_split_strategy2!$B:$B,A10,lookup_OPUS_split_strategy2!$F:$F) -> 2137.8 | E10: xcomet-xl | F10: =COUNTIF(lookup_OPUS_split_strategy2!$B:$B,E10) -> 4 | G10: =IF(H10="","",SUMIF(lookup_OPUS_split_strategy2!$B:$B,E10,lookup_OPUS_split_strategy2!$D:$D)/H10) -> 320.67263 | H10: =IFERROR(VLOOKUP(E10,new_analysis!$A:$D,4,FALSE),"") -> 400000
A11: Total | B11: =SUM(B2:B10) -> 9850 | C11: =SUM(C2:C10) -> 303569.3 | E11: Total | F11: =SUM(F2:F10) -> 9850 | G11: =SUM(G2:G10) -> 91728.25
